Workbook

Sheet Fixed cost calculation
A1: Capacity Factor | B1: 0.8 | C1: 0.8
A2: rate r | B2: 0.1 | C2: 0.09
A3: no of years | B3: 25 | C3: 25
A4: A/P | B4: =(B2*(1+B2)^B3)/((1+B2)^B3-1) -> 0.11016807 | C4: =(C2*(1+C2)^C3)/((1+C2)^C3-1) -> 0.10180625
A5: coal plant factor | B5: 0.8 | C5: 0.8
A7: Plant | B7: average (Fixed O&M (cr. ₹/MW/year) | C7: Fixed Cost in ₹/MWh | D7: CAPEX ( ₹/MW) | E7: Annual CAPEX ( ₹/MW) | F7: Annual CAPEX ( ₹/MWh) | G7: Efficiency | H7: Fuel Price | I7: Heat Rate | J7: CO2 cost | K7: Magrinal cost | L7: Profit Margin | M7: Add.cost in RS/MWh | N7: Marginal | O7: Additional Cost | P7: Variable cost | Q7: Bidding Marginal cost
A8: Coal_1 | B8: 0.22333333 | C8: =(B8*10^7)/(8760*$B$1) -> 318.68341 | D8: 84330423 | E8: =D8*$B$4 -> 9290520.1 | F8: =(E8)/(8760*$B$1) -> 1325.7021 | G8: 0.36 | H8: =ROUND(('Coal Prices'!$C$11/'Coal Prices'!$H$5)/G8*(860000/1000),2) -> 1665.33 | I8: 0 | J8: 0 | K8: =C8+H8+F8 -> 3309.7155 | L8: 0.15 | M8: =C8+F8 -> 1644.3855 | O8: =ROUND((C8+F8)/1000,2) -> 1.64 | P8: =H8/1000 -> 1.66533 | Q8: =K8+L8*K8 -> 3806.1728
A9: Coal_2 (lignite) | B9: 0.25 | C9: =(B9*10^7)/(8760*$B$1) -> 356.73516 | D9: 83003627 | E9: =D9*$B$4 -> 9144349.6 | F9: =(E9)/(8760*$B$1) -> 1304.8444 | G9: 0.3 | H9: =ROUND(('Coal Prices'!$C$11/'Coal Prices'!$H$5)/G9*(860000/1000),2) -> 1998.4 | I9: 0 | J9: 0 | K9: =C9+H9+F9 -> 3659.9796 | L9: 0.11 | M9: =C9+F9 -> 1661.5796 | O9: =ROUND((C9+F9)/1000,2) -> 1.66 | P9: =H9/1000 -> 1.9984 | Q9: =K9+L9*K9 -> 4062.5773
A10: Coal_3 (lignite) | B10: 0.25 | C10: =(B10*10^7)/(8760*$B$1) -> 356.73516 | D10: 83131232 | E10: =D10*$B$4 -> 9158407.6 | F10: =(E10)/(8760*$B$1) -> 1306.8504 | G10: 0.28 | H10: =ROUND(('Coal Prices'!$C$11/'Coal Prices'!$H$17)/G10*(860000/1000),2) -> 2319.57 | I10: 0 | J10: 0 | K10: =C10+H10+F10 -> 3983.1556 | L10: 0.12 | M10: =C10+F10 -> 1663.5856 | O10: =ROUND((C10+F10)/1000,2) -> 1.66 | P10: =H10/1000 -> 2.31957 | Q10: =K10+L10*K10 -> 4461.1342
A11: Coal_4 (imported) | B11: 0.27 | C11: =(B11*10^7)/(8760*$B$1) -> 385.27397 | D11: 91982617 | E11: =D11*$B$4 -> 10133548 | F11: =(E11)/(8760*$B$1) -> 1445.9971 | G11: 0.35 | H11: =ROUND(('Coal Prices'!$C$11/'Coal Prices'!$H$17)/G11*(860000/1000),2) -> 1855.65 | I11: 0 | J11: 0 | K11: =C11+H11+F11 -> 3686.9211 | L11: 0.15 | M11: =C11+F11 -> 1831.2711 | O11: =ROUND((C11+F11)/1000,2) -> 1.83 | P11: =H11/1000 -> 1.85565 | Q11: =K11+L11*K11 -> 4239.9592
A12: Coal_5 | B12: 0.21539064 | C12: =(B12*10^7)/(8760*$B$1) -> 307.34966 | D12: 84882697 | E12: =D12*$B$4 -> 9351363.1 | F12: =(E12)/(8760*$B$1) -> 1334.384 | G12: 0.29 | H12: =ROUND(('Coal Prices'!$C$11/'Coal Prices'!$H$5)/G12*(860000/1000),2) -> 2067.31 | I12: 0 | J12: 0 | K12: =C12+H12+F12 -> 3709.0437 | L12: 0.13 | M12: =C12+F12 -> 1641.7337 | O12: =ROUND((C12+F12)/1000,2) -> 1.64 | P12: =H12/1000 -> 2.06731 | Q12: =K12+L12*K12 -> 4191.2193
A13: Coal_6 | B13: 0.21294529 | C13: =(B13*10^7)/(8760*$B$1) -> 303.86029 | D13: 85195342 | E13: =D13*$B$4 -> 9385806.6 | F13: =(E13)/(8760*$B$1) -> 1339.2989 | G13: 0.31 | H13: =ROUND(('Coal Prices'!$C$11/'Coal Prices'!$H$5)/G13*(860000/1000),2) -> 1933.93 | I13: 0 | J13: 0 | K13: =C13+H13+F13 -> 3577.0892 | L13: 0.12 | M13: =C13+F13 -> 1643.1592 | O13: =ROUND((C13+F13)/1000,2) -> 1.64 | P13: =H13/1000 -> 1.93393 | Q13: =K13+L13*K13 -> 4006.3399
A14: Coal_7 | B14: 0.25544861 | C14: =(B14*10^7)/(8760*$B$1) -> 364.51 | D14: 85448559 | E14: =D14*$B$4 -> 9413703 | F14: =(E14)/(8760*$B$1) -> 1343.2795 | G14: 0.38 | H14: =ROUND(('Coal Prices'!$C$11/'Coal Prices'!$H$5)/G14*(860000/1000),2) -> 1577.68 | I14: 0 | J14: 0 | K14: =C14+H14+F14 -> 3285.4695 | L14: 0.13 | M14: =C14+F14 -> 1707.7895 | O14: =ROUND((C14+F14)/1000,2) -> 1.71 | P14: =H14/1000 -> 1.57768 | Q14: =K14+L14*K14 -> 3712.5806
A15: Coal_8 | B15: 0.25424885 | C15: =(B15*10^7)/(8760*$B$1) -> 362.79801 | D15: 85851440 | E15: =D15*$B$4 -> 9458087.6 | F15: =(E15)/(8760*$B$1) -> 1349.613 | G15: 0.37 | H15: =ROUND(('Coal Prices'!$C$11/'Coal Prices'!$H$5)/G15*(860000/1000),2) -> 1620.32 | I15: 0 | J15: 0 | K15: =C15+H15+F15 -> 3332.731 | L15: 0.13 | M15: =C15+F15 -> 1712.411 | O15: =ROUND((C15+F15)/1000,2) -> 1.71 | P15: =H15/1000 -> 1.62032 | Q15: =K15+L15*K15 -> 3765.986
A16: Coal_9 | B16: 0.20581826 | C16: =(B16*10^7)/(8760*$B$1) -> 293.69045 | D16: 87649405 | E16: =D16*$B$4 -> 9656166 | F16: =(E16)/(8760*$B$1) -> 1377.8776 | G16: 0.37 | H16: =ROUND(('Coal Prices'!$C$11/'Coal Prices'!$H$5)/G16*(860000/1000),2) -> 1620.32 | I16: 0 | J16: 0 | K16: =C16+H16+F16 -> 3291.888 | L16: 0.13 | M16: =C16+F16 -> 1671.568 | O16: =ROUND((C16+F16)/1000,2) -> 1.67 | P16: =H16/1000 -> 1.62032 | Q16: =K16+L16*K16 -> 3719.8335
A17: Coal_10 | B17: 0.23013405 | C17: =(B17*10^7)/(8760*$B$1) -> 328.38763 | D17: 88076236 | E17: =D17*$B$4 -> 9703189.1 | F17: =(E17)/(8760*$B$1) -> 1384.5875 | G17: 0.37 | H17: =ROUND(('Coal Prices'!$C$11/'Coal Prices'!$H$5)/G17*(860000/1000),2) -> 1620.32 | I17: 0 | J17: 0 | K17: =C17+H17+F17 -> 3333.2951 | L17: 0.14 | M17: =C17+F17 -> 1712.9751 | O17: =ROUND((C17+F17)/1000,2) -> 1.71 | P17: =H17/1000 -> 1.62032 | Q17: =K17+L17*K17 -> 3799.9564
A18: Coal_11 | B18: 0.26014978 | C18: =(B18*10^7)/(8760*$B$1) -> 371.21829 | D18: 89228633 | E18: =D18*$B$4 -> 9830146.5 | F18: =(E18)/(8760*$B$1) -> 1402.7036 | G18: 0.36 | H18: =ROUND(('Coal Prices'!$C$11/'Coal Prices'!$H$5)/G18*(860000/1000),2) -> 1665.33 | I18: 0 | J18: 0 | K18: =C18+H18+F18 -> 3439.2518 | L18: 0.13 | M18: =C18+F18 -> 1773.9218 | O18: =ROUND((C18+F18)/1000,2) -> 1.77 | P18: =H18/1000 -> 1.66533 | Q18: =K18+L18*K18 -> 3886.3546
A19: Coal_12 | B19: 0.21160168 | C19: =(B19*10^7)/(8760*$B$1) -> 301.94304 | D19: 90239346 | E19: =D19*$B$4 -> 9941494.8 | F19: =(E19)/(8760*$B$1) -> 1418.5923 | G19: 0.36 | H19: =ROUND(('Coal Prices'!$C$11/'Coal Prices'!$H$5)/G19*(860000/1000),2) -> 1665.33 | I19: 0 | J19: 0 | K19: =C19+H19+F19 -> 3385.8653 | L19: 0.1 | M19: =C19+F19 -> 1720.5353 | O19: =ROUND((C19+F19)/1000,2) -> 1.72 | P19: =H19/1000 -> 1.66533 | Q19: =K19+L19*K19 -> 3724.4519
A20: Coal_13 | B20: 0.21050668 | C20: =(B20*10^7)/(8760*$B$1) -> 300.38053 | D20: 91244631 | E20: =D20*$B$4 -> 10052245 | F20: =(E20)/(8760*$B$1) -> 1434.3957 | G20: 0.36 | H20: =ROUND(('Coal Prices'!$C$11/'Coal Prices'!$H$5)/G20*(860000/1000),2) -> 1665.33 | I20: 0 | J20: 0 | K20: =C20+H20+F20 -> 3400.1062 | L20: 0.11 | M20: =C20+F20 -> 1734.7762 | O20: =ROUND((C20+F20)/1000,2) -> 1.73 | P20: =H20/1000 -> 1.66533 | Q20: =K20+L20*K20 -> 3774.1179
A21: Coal_14 | B21: 0.21645405 | C21: =(B21*10^7)/(8760*$B$1) -> 308.86708 | D21: 91309477 | E21: =D21*$B$4 -> 10059389 | F21: =(E21)/(8760*$B$1) -> 1435.4151 | G21: 0.35 | H21: =ROUND(('Coal Prices'!$C$11/'Coal Prices'!$H$5)/G21*(860000/1000),2) -> 1712.91 | I21: 0 | J21: 0 | K21: =C21+H21+F21 -> 3457.1922 | L21: 0.13 | M21: =C21+F21 -> 1744.2822 | O21: =ROUND((C21+F21)/1000,2) -> 1.74 | P21: =H21/1000 -> 1.71291 | Q21: =K21+L21*K21 -> 3906.6272
A22: Coal_15 | B22: 0.24784308 | C22: =(B22*10^7)/(8760*$B$1) -> 353.65736 | D22: 91982617 | E22: =D22*$B$4 -> 10133548 | F22: =(E22)/(8760*$B$1) -> 1445.9971 | G22: 0.32 | H22: =ROUND(('Coal Prices'!$C$11/'Coal Prices'!$H$5)/G22*(860000/1000),2) -> 1873.5 | I22: 0 | J22: 0 | K22: =C22+H22+F22 -> 3673.1544 | L22: 0.13 | M22: =C22+F22 -> 1799.6544 | O22: =ROUND((C22+F22)/1000,2) -> 1.8 | P22: =H22/1000 -> 1.8735 | Q22: =K22+L22*K22 -> 4150.6645
A24: Gas Turbine
A25: CCGTurbine_1 | B25: 0.18 | C25: =(B25*10^7)/(8760*$B$1) -> 256.84932 | D25: =5*10^7 -> 50000000 | E25: =D25*$B$4 -> 5508403.6 | F25: =(E25)/(8760*$B$1) -> 786.0165 | G25: 0.5 | H25: =ROUND(I25*'Gas Price'!$B$4/252/'Fixed cost calculation'!$G$25,2) -> 7263.06 | I25: 1375 | J25: 0 | K25: =C25+H25+F25 -> 8305.9258 | L25: 0.05 | M25: =C25+F25 -> 1042.8658 | O25: =ROUND((C25+F25)/1000,2) -> 1.04 | P25: =H25/1000 -> 7.26306 | Q25: =K25+L25*K25 -> 8721.2221
A26: Gas Turbine_2 | C26: =(B26*10^7)/(8760*$B$1) -> 0 | E26: =D26*$B$4 -> 0 | F26: =(E26)/(8760*$B$1) -> 0 | G26: =ROUND(RAND() * (0.45 - 0.28) + 0.28,2) -> 0.41 | H26: =ROUND(I26*'Gas Price'!$B$4/252/'Fixed cost calculation'!$G$25,2) -> 13406.28 | I26: 2538 | J26: 0 | K26: =C26+H26+F26 -> 13406.28 | L26: 0.05 | M26: =C26+F26 -> 0 | O26: =ROUND((C26+F26)/1000,2) -> 0 | P26: =H26/1000 -> 13.40628 | Q26: =K26+L26*K26 -> 14076.594
A27: Gas Turbine_3 | B27: 0.1 | C27: =(B27*10^7)/(8760*$B$1) -> 142.69406 | E27: =D27*$B$4 -> 0 | F27: =(E27)/(8760*$B$1) -> 0 | G27: =ROUND(RAND() * (0.45 - 0.28) + 0.28,2) -> 0.44 | H27: =ROUND(I27*'Gas Price'!$B$4/252/'Fixed cost calculation'!$G$25,2) -> 13474.95 | I27: 2551 | J27: 0 | K27: =C27+H27+F27 -> 13617.644 | L27: 0.05 | M27: =C27+F27 -> 142.69406 | O27: =ROUND((C27+F27)/1000,2) -> 0.14 | P27: =H27/1000 -> 13.47495 | Q27: =K27+L27*K27 -> 14298.526
A28: Gas Turbine_4 | C28: =(B28*10^7)/(8760*$B$1) -> 0 | E28: =D28*$B$4 -> 0 | F28: =(E28)/(8760*$B$1) -> 0 | G28: =ROUND(RAND() * (0.45 - 0.28) + 0.28,2) -> 0.36 | H28: =ROUND(I28*'Gas Price'!$B$4/252/'Fixed cost calculation'!$G$25,2) -> 10759.89 | I28: 2037 | J28: 0 | K28: =C28+H28+F28 -> 10759.89 | L28: 0.05 | M28: =C28+F28 -> 0 | O28: =ROUND((C28+F28)/1000,2) -> 0 | P28: =H28/1000 -> 10.75989 | Q28: =K28+L28*K28 -> 11297.885
A29: Gas Turbine_5 | C29: =(B29*10^7)/(8760*$B$1) -> 0 | E29: =D29*$B$4 -> 0 | F29: =(E29)/(8760*$B$1) -> 0 | G29: =ROUND(RAND() * (0.45 - 0.28) + 0.28,2) -> 0.44 | H29: =ROUND(I29*'Gas Price'!$B$4/252/'Fixed cost calculation'!$G$25,2) -> 14489.14 | I29: 2743 | J29: 0 | K29: =C29+H29+F29 -> 14489.14 | L29: 0.05 | M29: =C29+F29 -> 0 | O29: =ROUND((C29+F29)/1000,2) -> 0 | P29: =H29/1000 -> 14.48914 | Q29: =K29+L29*K29 -> 15213.597
A30: Gas Turbine_6 | B30: 0.371 | C30: =(B30*10^7)/(8760*$B$1) -> 529.39498 | E30: =D30*$B$4 -> 0 | F30: =(E30)/(8760*$B$1) -> 0 | G30: =ROUND(RAND() * (0.45 - 0.28) + 0.28,2) -> 0.32 | H30: =ROUND(I30*'Gas Price'!$B$4/252/'Fixed cost calculation'!$G$25,2) -> 14504.98 | I30: 2746 | J30: 0 | K30: =C30+H30+F30 -> 15034.375 | L30: 0.05 | M30: =C30+F30 -> 529.39498 | O30: =ROUND((C30+F30)/1000,2) -> 0.53 | P30: =H30/1000 -> 14.50498 | Q30: =K30+L30*K30 -> 15786.094
A31: Gas Turbine_7 | C31: =(B31*10^7)/(8760*$B$1) -> 0 | E31: =D31*$B$4 -> 0 | F31: =(E31)/(8760*$B$1) -> 0 | G31: =ROUND(RAND() * (0.45 - 0.28) + 0.28,2) -> 0.35 | H31: =ROUND(I31*'Gas Price'!$B$4/252/'Fixed cost calculation'!$G$25,2) -> 10601.42 | I31: 2007 | J31: 0 | K31: =C31+H31+F31 -> 10601.42 | L31: 0.05 | M31: =C31+F31 -> 0 | O31: =ROUND((C31+F31)/1000,2) -> 0 | P31: =H31/1000 -> 10.60142 | Q31: =K31+L31*K31 -> 11131.491
A32: Gas Turbine_8 | B32: 0.043 | C32: =(B32*10^7)/(8760*$B$1) -> 61.358447 | E32: =D32*$B$4 -> 0 | F32: =(E32)/(8760*$B$1) -> 0 | G32: =ROUND(RAND() * (0.45 - 0.28) + 0.28,2) -> 0.39 | H32: =ROUND(I32*'Gas Price'!$B$4/252/'Fixed cost calculation'!$G$25,2) -> 13797.16 | I32: 2612 | J32: 0 | K32: =C32+H32+F32 -> 13858.518 | L32: 0.05 | M32: =C32+F32 -> 61.358447 | O32: =ROUND((C32+F32)/1000,2) -> 0.06 | P32: =H32/1000 -> 13.79716 | Q32: =K32+L32*K32 -> 14551.444
A33: Gas Turbine_9 | C33: =(B33*10^7)/(8760*$B$1) -> 0 | E33: =D33*$B$4 -> 0 | F33: =(E33)/(8760*$B$1) -> 0 | G33: =ROUND(RAND() * (0.45 - 0.28) + 0.28,2) -> 0.4 | H33: =ROUND(I33*'Gas Price'!$B$4/252/'Fixed cost calculation'!$G$25,2) -> 15809.69 | I33: 2993 | J33: 0 | K33: =C33+H33+F33 -> 15809.69 | L33: 0.05 | M33: =C33+F33 -> 0 | O33: =ROUND((C33+F33)/1000,2) -> 0 | P33: =H33/1000 -> 15.80969 | Q33: =K33+L33*K33 -> 16600.175
A34: Gas Turbine_10 | B34: 0.15017451 | C34: =(B34*10^7)/(8760*$B$1) -> 214.29011 | D34: =RANDBETWEEN(4.1*10^7,5*10^7) -> 44790589 | E34: =D34*$B$4 -> 4934492.8 | F34: =(E34)/(8760*$B$1) -> 704.12284 | G34: 0.5 | H34: =ROUND(I34*'Gas Price'!$B$4/252/'Fixed cost calculation'!$G$25,2) -> 9867.19 | I34: 1868 | J34: 0 | K34: =C34+H34+F34 -> 10785.603 | L34: 0.05 | M34: =C34+F34 -> 918.41294 | O34: =ROUND((C34+F34)/1000,2) -> 0.92 | P34: =H34/1000 -> 9.86719 | Q34: =K34+L34*K34 -> 11324.883
A35: Gas Turbine_11 | B35: 0.10826235 | C35: =(B35*10^7)/(8760*$B$1) -> 154.48394 | D35: =RANDBETWEEN(4.1*10^7,5*10^7) -> 49066080 | E35: =D35*$B$4 -> 5405515.4 | F35: =(E35)/(8760*$B$1) -> 771.33497 | G35: 0.5 | H35: =ROUND(I35*'Gas Price'!$B$4/252/'Fixed cost calculation'!$G$25,2) -> 9867.19 | I35: 1868 | J35: 0 | K35: =C35+H35+F35 -> 10793.009 | L35: 0.05 | M35: =C35+F35 -> 925.81891 | O35: =ROUND((C35+F35)/1000,2) -> 0.93 | P35: =H35/1000 -> 9.86719 | Q35: =K35+L35*K35 -> 11332.659
A36: CCGTurbine_2 | B36: 0.08150416 | C36: =(B36*10^7)/(8760*$B$1) -> 116.3016 | D36: =RANDBETWEEN(4.1*10^7,4.5*10^7) -> 43592055 | E36: =D36*$B$4 -> 4802452.7 | F36: =(E36)/(8760*$B$1) -> 685.28149 | G36: 0.43 | H36: =ROUND(I36*'Gas Price'!$B$4/252/'Fixed cost calculation'!$G$25,2) -> 7368.7 | I36: 1395 | J36: 0 | K36: =C36+H36+F36 -> 8170.2831 | L36: 0.05 | M36: =C36+F36 -> 801.58308 | O36: =ROUND((C36+F36)/1000,2) -> 0.8 | P36: =H36/1000 -> 7.3687 | Q36: =K36+L36*K36 -> 8578.7972
A37: CCGTurbine_3 | B37: 0.05 | C37: =(B37*10^7)/(8760*$B$1) -> 71.347032 | D37: 40000000 | E37: =D37*$C$4 -> 4072250 | F37: =(E37)/(8760*$B$1) -> 581.0859 | G37: 0.38 | H37: =ROUND(I37*'Gas Price'!$B$4/252/'Fixed cost calculation'!$G$25,2) -> 6866.89 | I37: 1300 | J37: 0 | K37: =C37+H37+F37 -> 7519.3229 | L37: 0.02 | M37: =C37+F37 -> 652.43294 | O37: =ROUND((C37+F37)/1000,2) -> 0.65 | P37: =H37/1000 -> 6.86689 | Q37: =K37+L37*K37 -> 7669.7094
A38: CCGTurbine_4 | B38: 0.17273552 | C38: =(B38*10^7)/(8760*$B$1) -> 246.48333 | D38: =RANDBETWEEN(4.1*10^7,4.5*10^7) -> 42558513 | E38: =D38*$B$4 -> 4688589.3 | F38: =(E38)/(8760*$B$1) -> 669.03387 | G38: 0.41 | H38: =ROUND(I38*'Gas Price'!$B$4/252/'Fixed cost calculation'!$G$25,2) -> 8055.39 | I38: 1525 | J38: 0 | K38: =C38+H38+F38 -> 8970.9072 | L38: 0.05 | M38: =C38+F38 -> 915.51719 | O38: =ROUND((C38+F38)/1000,2) -> 0.92 | P38: =H38/1000 -> 8.05539 | Q38: =K38+L38*K38 -> 9419.4526
A39: CCGTurbine_5 | B39: 0.093666906 | C39: =(B39*10^7)/(8760*$B$1) -> 133.65711 | D39: =RANDBETWEEN(4.1*10^7,4.5*10^7) -> 41668407 | E39: =D39*$B$4 -> 4590528.1 | F39: =(E39)/(8760*$B$1) -> 655.04111 | G39: 0.34 | H39: =ROUND(I39*'Gas Price'!$B$4/252/'Fixed cost calculation'!$G$25,2) -> 7469.06 | I39: 1414 | J39: 0 | K39: =C39+H39+F39 -> 8257.7582 | L39: 0.05 | M39: =C39+F39 -> 788.69822 | O39: =ROUND((C39+F39)/1000,2) -> 0.79 | P39: =H39/1000 -> 7.46906 | Q39: =K39+L39*K39 -> 8670.6461
A40: CCGTurbine_6 | B40: 0.12882717 | C40: =(B40*10^7)/(8760*$B$1) -> 183.82873 | D40: =RANDBETWEEN(4.1*10^7,4.5*10^7) -> 41465230 | E40: =D40*$B$4 -> 4568144.5 | F40: =(E40)/(8760*$B$1) -> 651.8471 | G40: 0.39 | H40: =ROUND(I40*'Gas Price'!$B$4/252/'Fixed cost calculation'!$G$25,2) -> 7648.66 | I40: 1448 | J40: 0 | K40: =C40+H40+F40 -> 8484.3358 | L40: 0.05 | M40: =C40+F40 -> 835.67582 | O40: =ROUND((C40+F40)/1000,2) -> 0.84 | P40: =H40/1000 -> 7.64866 | Q40: =K40+L40*K40 -> 8908.5526
A41: CCGTurbine_8 | B41: 0.1374434 | C41: =(B41*10^7)/(8760*$B$1) -> 196.12357 | D41: =RANDBETWEEN(4.1*10^7,4.5*10^7) -> 44034368 | E41: =D41*$B$4 -> 4851181.4 | F41: =(E41)/(8760*$B$1) -> 692.23479 | G41: 0.3 | H41: =ROUND(I41*'Gas Price'!$B$4/252/'Fixed cost calculation'!$G$25,2) -> 8192.73 | I41: 1551 | J41: 0 | K41: =C41+H41+F41 -> 9081.0884 | L41: 0.05 | M41: =C41+F41 -> 888.35836 | O41: =ROUND((C41+F41)/1000,2) -> 0.89 | P41: =H41/1000 -> 8.19273 | Q41: =K41+L41*K41 -> 9535.1428
A42: CCGTurbine_9 | B42: 0.075158474 | C42: =(B42*10^7)/(8760*$B$1) -> 107.24668 | D42: =RANDBETWEEN(4.1*10^7,4.5*10^7) -> 44319181 | E42: =D42*$B$4 -> 4882558.7 | F42: =(E42)/(8760*$B$1) -> 696.71215 | G42: 0.42 | H42: =ROUND(I42*'Gas Price'!$B$4/252/'Fixed cost calculation'!$G$25,2) -> 8367.04 | I42: 1584 | J42: 0 | K42: =C42+H42+F42 -> 9170.9988 | L42: 0.05 | M42: =C42+F42 -> 803.95883 | O42: =ROUND((C42+F42)/1000,2) -> 0.8 | P42: =H42/1000 -> 8.36704 | Q42: =K42+L42*K42 -> 9629.5488
...

Sheet Sheet2
B4: Plant | C4: Magrinal cost | D4: Bidding Marginal cost | E4: Bid Vol
B5: ='Fixed cost calculation'!A8 -> Coal_1 | C5: ='Fixed cost calculation'!K8 -> 3309.7155 | D5: ='Fixed cost calculation'!Q8 -> 3806.1728 | E5: v1 | F5: ?
B6: ='Fixed cost calculation'!A9 -> Coal_2 (lignite) | C6: ='Fixed cost calculation'!K9 -> 3659.9796 | D6: ='Fixed cost calculation'!Q9 -> 4062.5773 | E6: v2
B7: ='Fixed cost calculation'!A10 -> Coal_3 (lignite) | C7: ='Fixed cost calculation'!K10 -> 3983.1556 | D7: ='Fixed cost calculation'!Q10 -> 4461.1342 | E7: v3
B8: ='Fixed cost calculation'!A11 -> Coal_4 (imported) | C8: ='Fixed cost calculation'!K11 -> 3686.9211 | D8: ='Fixed cost calculation'!Q11 -> 4239.9592 | E8: v4
B9: ='Fixed cost calculation'!A12 -> Coal_5 | C9: ='Fixed cost calculation'!K12 -> 3709.0437 | D9: ='Fixed cost calculation'!Q12 -> 4191.2193 | E9: v5
B10: ='Fixed cost calculation'!A13 -> Coal_6 | C10: ='Fixed cost calculation'!K13 -> 3577.0892 | D10: ='Fixed cost calculation'!Q13 -> 4006.3399 | E10: v6
B11: ='Fixed cost calculation'!A14 -> Coal_7 | C11: ='Fixed cost calculation'!K14 -> 3285.4695 | D11: ='Fixed cost calculation'!Q14 -> 3712.5806 | E11: v7
B12: ='Fixed cost calculation'!A15 -> Coal_8 | C12: ='Fixed cost calculation'!K15 -> 3332.731 | D12: ='Fixed cost calculation'!Q15 -> 3765.986 | E12: v8
B13: ='Fixed cost calculation'!A16 -> Coal_9 | C13: ='Fixed cost calculation'!K16 -> 3291.888 | D13: ='Fixed cost calculation'!Q16 -> 3719.8335 | E13: v9
B14: ='Fixed cost calculation'!A17 -> Coal_10 | C14: ='Fixed cost calculation'!K17 -> 3333.2951 | D14: ='Fixed cost calculation'!Q17 -> 3799.9564 | E14: v10
B15: ='Fixed cost calculation'!A18 -> Coal_11 | C15: ='Fixed cost calculation'!K18 -> 3439.2518 | D15: ='Fixed cost calculation'!Q18 -> 3886.3546 | E15: v11
B16: ='Fixed cost calculation'!A19 -> Coal_12 | C16: ='Fixed cost calculation'!K19 -> 3385.8653 | D16: ='Fixed cost calculation'!Q19 -> 3724.4519 | E16: v12
B17: ='Fixed cost calculation'!A20 -> Coal_13 | C17: ='Fixed cost calculation'!K20 -> 3400.1062 | D17: ='Fixed cost calculation'!Q20 -> 3774.1179 | E17: v13
... B19: ='Fixed cost calculation'!A22 -> Coal_15 | C19: ='Fixed cost calculation'!K22 -> 3673.1544 | D19: ='Fixed cost calculation'!Q22 -> 4150.6645 | E19: v15
B20: ='Fixed cost calculation'!A25 -> CCGTurbine_1 | C20: ='Fixed cost calculation'!K25 -> 8305.9258 | D20: ='Fixed cost calculation'!Q25 -> 8721.2221 | E20: v16
B21: ='Fixed cost calculation'!A26 -> Gas Turbine_2 | C21: ='Fixed cost calculation'!K26 -> 13406.28 | D21: ='Fixed cost calculation'!Q26 -> 14076.594 | E21: v17
B22: ='Fixed cost calculation'!A27 -> Gas Turbine_3 | C22: ='Fixed cost calculation'!K27 -> 13617.644 | D22: ='Fixed cost calculation'!Q27 -> 14298.526 | E22: v18
B23: ='Fixed cost calculation'!A28 -> Gas Turbine_4 | C23: ='Fixed cost calculation'!K28 -> 10759.89 | D23: ='Fixed cost calculation'!Q28 -> 11297.885 | E23: v19
B24: ='Fixed cost calculation'!A29 -> Gas Turbine_5 | C24: ='Fixed cost calculation'!K29 -> 14489.14 | D24: ='Fixed cost calculation'!Q29 -> 15213.597 | E24: v20
B25: ='Fixed cost calculation'!A30 -> Gas Turbine_6 | C25: ='Fixed cost calculation'!K30 -> 15034.375 | D25: ='Fixed cost calculation'!Q30 -> 15786.094 | E25: v21
B26: ='Fixed cost calculation'!A31 -> Gas Turbine_7 | C26: ='Fixed cost calculation'!K31 -> 10601.42 | D26: ='Fixed cost calculation'!Q31 -> 11131.491 | E26: v22
B27: ='Fixed cost calculation'!A32 -> Gas Turbine_8 | C27: ='Fixed cost calculation'!K32 -> 13858.518 | D27: ='Fixed cost calculation'!Q32 -> 14551.444 | E27: v23
B28: ='Fixed cost calculation'!A33 -> Gas Turbine_9 | C28: ='Fixed cost calculation'!K33 -> 15809.69 | D28: ='Fixed cost calculation'!Q33 -> 16600.175 | E28: v24
B29: ='Fixed cost calculation'!A34 -> Gas Turbine_10 | C29: ='Fixed cost calculation'!K34 -> 10785.603 | D29: ='Fixed cost calculation'!Q34 -> 11324.883 | E29: v25
B30: ='Fixed cost calculation'!A35 -> Gas Turbine_11 | C30: ='Fixed cost calculation'!K35 -> 10793.009 | D30: ='Fixed cost calculation'!Q35 -> 11332.659 | E30: v26
B31: ='Fixed cost calculation'!A36 -> CCGTurbine_2 | C31: ='Fixed cost calculation'!K36 -> 8170.2831 | D31: ='Fixed cost calculation'!Q36 -> 8578.7972 | E31: v27
... B39: ='Fixed cost calculation'!A44 -> Gas Turbine_20 | C39: ='Fixed cost calculation'!K44 -> 8350.8185 | D39: ='Fixed cost calculation'!Q44 -> 8768.3594 | E39: v35
B40: ='Fixed cost calculation'!A51 -> Hydro_1 | C40: ='Fixed cost calculation'!K51 -> 2217.178 | D40: ='Fixed cost calculation'!Q51 -> 2549.7547 | E40: v36
B41: ='Fixed cost calculation'!A52 -> Hydro_2 | C41: ='Fixed cost calculation'!K52 -> 1079.7678 | D41: ='Fixed cost calculation'!Q52 -> 1284.9237 | E41: v37
B42: ='Fixed cost calculation'!A53 -> Hydro_3 | C42: ='Fixed cost calculation'!K53 -> 1934.9935 | D42: ='Fixed cost calculation'!Q53 -> 2167.1927 | E42: v38
B43: ='Fixed cost calculation'!A54 -> Hydro_4 | C43: ='Fixed cost calculation'!K54 -> 2280.3857 | D43: ='Fixed cost calculation'!Q54 -> 2531.2281 | E43: v39
B44: ='Fixed cost calculation'!A55 -> Hydro_5 | C44: ='Fixed cost calculation'!K55 -> 1331.6614 | D44: ='Fixed cost calculation'!Q55 -> 1664.5768 | E44: v40
B45: ='Fixed cost calculation'!A56 -> Hydro_6 | C45: ='Fixed cost calculation'!K56 -> 1655.9384 | D45: ='Fixed cost calculation'!Q56 -> 2020.2449 | E45: v41
B46: ='Fixed cost calculation'!A57 -> Hydro_7 | C46: ='Fixed cost calculation'!K57 -> 1776.6773 | D46: ='Fixed cost calculation'!Q57 -> 1954.345 | E46: v42
B47: ='Fixed cost calculation'!A58 -> Hydro_8 | C47: ='Fixed cost calculation'!K58 -> 1885.8928 | D47: ='Fixed cost calculation'!Q58 -> 2112.2 | E47: v43
B48: ='Fixed cost calculation'!A59 -> Hydro_9 | C48: ='Fixed cost calculation'!K59 -> 1463.3265 | D48: ='Fixed cost calculation'!Q59 -> 1770.6251 | E48: v44
B49: ='Fixed cost calculation'!A60 -> Hydro_10 | C49: ='Fixed cost calculation'!K60 -> 1293.3716 | D49: ='Fixed cost calculation'!Q60 -> 1526.1784 | E49: v45
B50: ='Fixed cost calculation'!A61 -> Hydro_11 | C50: ='Fixed cost calculation'!K61 -> 1685.0161 | D50: ='Fixed cost calculation'!Q61 -> 2106.2702 | E50: v46
B51: ='Fixed cost calculation'!A62 -> Hydro_12 | C51: ='Fixed cost calculation'!K62 -> 2005.5247 | D51: ='Fixed cost calculation'!Q62 -> 2226.1324 | E51: v47
...

Sheet Cost Range
A1: Technology | B1: Size (1 Unit) MW | C1: Electrical Efficiency | D1: Capital cost (cr. ₹/MW) | E1: Fixed O&M (cr. ₹/MW/year) | F1: Variable O&M (₹/MWh) | G1: Hot Startup cost (cr.₹/MW/startup) | H1: Warm Startup cost (cr.₹/MW/startup) | I1: Cold Startup cost (cr.₹/MW/startup)
A2: Coal | B2: 210-600 | C2: 0.36 | D2: 9.2 | E2: 0.27 | G2: 25000 | H2: 30000 | I2: 52000
B3: 660-800 | C3: 0.38 | D3: 8.3 | E3: 0.2 | G3: 25000 | H3: 30000 | I3: 52000
B4: 660-800 | C4: 0.413 | D4: 8.4 | E4: 0.2
A6: Gas Power | B6: 50-200+ | C6: 0.28 | D6: 5 | E6: 0.18 | G6: 2473
B7: 50-870 | C7: 0.6 | D7: 3.47 | E7: 0.29 | G7: 1556 | H7: 7782 | I7: 12451
B8: 10 | C8: 0.45 | D8: 4.1 | E8: 0.07 | F8: 557
A10: Bio Mass | B10: 10 | C10: 0.265 | D10: 5 | E10: 0.1 | G10: 2217 | H10: 3325 | I10: 4433
A12: Wind Turbine onshore | B12: 2.5 | D12: 6.66 | E12: 0.068 | F12: 240
A13: Wind turbines, offshore | B13: 8 | D13: 23.1 | E13: 0.674
A15: PV | B15: 50-150 | D15: 5.4 | E15: 0.035
A17: Hydro Power Plants Run-of-river without storage | B17: 35-120 | C17: 0.973 | D17: 10.7 | E17: 0.44
A18: Hydro power plants, ROR with storage | B18: 20-250 | C18: 0.98 | D18: 11.9 | E18: 0.41
A19: Small Hydro power plants, reservoir (<25 MW) | B19: 1-5 | C19: 0.45 | D19: 8.04 | E19: 0.24
A21: Large Hydro power plants, reservoir (>25 MW) | B21: 35 - 200 | C21: 0.969 | D21: 8.3 | E21: 0.91
A22: Hydro power plants, Pumped storage on-river | D22: 6 | E22: 0.15
A23: Hydro power plants, Pumped storage closed loop | D23: 3.85 | E23: 0.1
A25: Nuclear power plant, Pressurized heavy-water reactor | B25: 460 | C25: 0.31 | D25: 11.7 | E25: 0.43
A26: Nuclear power plant, Light-water Reactor | B26: 1000 - 1600 | C26: 0.31 | D26: 19 | E26: 0.26
A28: BESS | B28: 1-100 | C28: 0.9 | D28: 6.73 | E28: 0.08 | F28: 500

Sheet Sheet1
A2: Technology | B2: average (Fixed O&M (cr. ₹/MW/year) | C2: Fixed Cost in ₹/MWh | D2: CAPEX ( ₹/MW) | E2: Annual CAPEX ( ₹/MW) | F2: Annual CAPEX ( ₹/MWh) | G2: Efficiency | H2: Fuel Price | I2: CO2 cost | J2: Magrinal cost | K2: Profit Margin | L2: Additional Cost | M2: Variable cost | N2: Bidding Marginal cost
A3: Solar | B3: 0.035 | C3: 49.942922 | D3: 54000000 | E3: 5949075.9 | F3: 848.89782 | G3: 0.23 | H3: 0 | I3: 0 | J3: 898.84074 | K3: 0.1 | L3: 0.89884074 | M3: 0 | N3: 988.72481
A4: Wind | B4: 0.068 | C4: 97.031963 | D4: 66600000 | E4: 7337193.6 | F4: 1046.974 | G4: 0.35 | H4: 0 | I4: 0 | J4: 1144.0059 | K4: 0.2 | L4: 1.1440059 | M4: 0 | N4: 1372.8071
A5: Hydro | B5: 0.375 | C5: 535.10274 | D5: 107000000 | E5: 11787984 | F5: 1682.0753 | G5: 0.8 | H5: 0 | I5: 0 | J5: 2217.178 | K5: 0.2 | L5: 2.217178 | M5: 0 | N5: 2660.6137
A6: Coal | B6: 0.22333333 | C6: 318.68341 | D6: 86000000 | E6: 9474454.2 | F6: 1351.9484 | G6: 0.35 | H6: 1712.9121 | I6: 0 | J6: 3383.5439 | K6: 0.1 | L6: 1.6706318 | M6: 1.7129121 | N6: 3721.8983
A7: Coal | B7: 0.27 | C7: 385.27397 | D7: 92000000 | E7: 10135463 | F7: 1446.2704 | G7: 0.32 | H7: 1873.4976 | I7: 0 | J7: 3705.0419 | K7: 0.1 | L7: 1.8315443 | M7: 1.8734976 | N7: 4075.5461
A8: Nuclear | B8: 0.345 | C8: 492.29452 | D8: 190000000 | E8: 20931934 | F8: 2986.8627 | G8: 0.45 | H8: 0 | I8: 0 | J8: 3479.1572 | K8: 0.2 | L8: 3.4791572 | M8: 0 | N8: 4174.9887
A9: Gas Turbine | B9: 0.18 | C9: 256.84932 | D9: 50000000 | E9: 5508403.6 | F9: 786.0165 | G9: 0.38 | H9: 2784.7699 | I9: 0 | J9: 3827.6357 | K9: 0.15 | L9: 1.0428658 | M9: 2.7847699 | N9: 4401.781

Sheet Financial Parameters Generators
A1: Data Source | B1: https://drive.google.com/file/d/1HcrTbXi6cDYhCJUCOnkTY3b5tOywMZJf/view?usp=sharing
A3: Technology | B3: Capital cost (cr. ₹/MW) | C3: Fixed O&M (cr. ₹/MW/year)
D4: Hot Startup cost (cr. ₹/MW/startup) | E4: Warm Startup cost (cr. ₹/MW/startup) | F4: Codl Startup cost (cr. ₹/MW/startup) | G4: Variable O &M Cost (₹/MWh)
A5: Pulverized coal fired, subcritical steam process, condensing plant | B5: 9.2 | C5: 0.27 | D5: 25000 | E5: 30000 | F5: 52000
A6: 01b Pulverized coal fired, supercritical steam process, condensing plant | B6: 8.3 | C6: 0.2 | D6: 25000 | E6: 30000 | F6: 52000
A7: 01c Pulverized coal fired, ultra-supercritical steam process, condensing plant | B7: 8.4 | C7: 0.2 | D7: - | E7: - | F7: - | G7: -
A8: 02a Gas turbine, open cycle (large), back pressure | B8: 5 | C8: 0.18 | D8: 2473 | E8: - | F8: - | G8: -
A9: 02b Gas turbine, combined cycle, condensing plant | B9: 3.47 | C9: 0.29 | D9: 1556 | E9: 7782 | F9: 12451 | G9: 0.21
A10: 02c Gas Engine | B10: 4.1 | C10: 0.07 | D10: - | E10: - | F10: - | G10: 557
A11: 03 Biomass plant | B11: 5 | C11: 0.1 | D11: 2217 | E11: 3325 | F11: 4433
A12: 04 Large wind turbines on land | B12: 6.66 | C12: 0.068 | D12: - | E12: - | F12: - | G12: 240
A13: 05 Large wind turbines offshore | B13: 23.1 | C13: 0.674 | D13: - | E13: - | F13: - | G13: -
A14: 06a Photovoltaics: Large scale utility systems | B14: 5.4 | C14: 0.035
A15: 06b Photovoltaics: Rooftop System | B15: 3.9 | C15: 0.051
A16: 07a Hydro power plants, Run-of-river without storage | B16: 10.7 | C16: 0.44
A17: 07b Hydro power plants, ROR with storage | B17: 11.9 | C17: 0.41
A18: 07c Small Hydro power plants, reservoir (<25 MW) | B18: 8.04 | C18: 0.24
A19: 07d Large Hydro power plants, reservoir (>25 MW) | B19: 8.3 | C19: 0.91
A20: 07e Hydro power plants, Pumped storage on-river | B20: 6 | C20: 0.15
A21: 7f Hydro power plants, Pumped storage closed loop | B21: 3.85 | C21: 0.1
A22: 08a Nuclear power plant, Pressurized heavy-water reactor | B22: 11.7 | C22: 0.43
A23: 08b Nuclear power plant, Light-water Reactor | B23: 19 | C23: 0.26
A24: 09 Battery storage system (Lithium-ion) | C24: 0.08 | G24: 500

Sheet Renewable share
A1: Source | C1: https://drive.google.com/file/d/1H94p2NGkwG1ykCGv09jNeb_6l2uJo5o5/view?usp=sharing
A2: Data as of | B2: 45778
A3: Total | B3: =SUM(B4:B7) -> 172.37
A4: Solar | B4: 105.65 | C4: GW
A5: BioMass | B5: 11.58 | C5: GW
A6: Wind | B6: 50.04 | C6: GW
A7: Small Hydro | B7: 5.1 | C7: GW
A10: Solar+Wind | B10: 155.69
A11: Solar/Wind | B11: =B4/B6 -> 2.111311
A13: If solar +wind = | B13: 297.128 | C13: MW
A14: and Solar/Wind = | B14: =B11 -> 2.111311
A15: Then
A16: Solar =
A17: Wind =
A19: Wind = | B19: =B13/(B14+1) -> 95.499294 | C19: MW
A20: Solar = | B20: =B13-B19 -> 201.62871 | C20: MW

Sheet Coal Prices
A1: Source | C1: https://drive.google.com/file/d/1hU4YMXpBnXoH4fNPDDoh5U8MwEvjewMP/view?usp=sharing
C2: https://drive.google.com/file/d/11_-cSwfuGbUOeZDIztLrIDRQaRhIc73M/view?usp=sharing
B3: Rs/ton | C3: Rs/ton
A4: Grade | B4: 46143 | C4: 46174 | D4: kCal/kg | F4: For Grade 7 Coal | H4: between 5200 to 5500 | I4: kCal/kg
A5: G1 | B5: 11228 | C5: 10701 | D5: Exceeding 7000 | F5: Energy Content | H5: 5200 | I5: kCal/kg | K5: Energy Content(MWh per ton) | N5: (kCal/kg)*1000/860000
A6: G2 | B6: 7014 | C6: 7280 | F6: Energy Content | H6: =H5*1000/860000 -> 6.0465116 | I6: MWh/ton
A7: G3 | B7: 6610 | C7: 6882
A8: G4 | B8: 6502 | C8: 6834 | F8: Coal cost (₹/MWh) | H8: Coal Price/Energy Content(MWh per ton)
A9: G5 | B9: 6242 | C9: 6541 | H9: =$C$11/H6 -> 599.51923 | I9: ₹/MWh
A10: G6 | B10: 5699 | C10: 5952
A11: G7 | B11: 3483 | C11: 3625 | D11: Exceeding 5200 and not exceeding 5500
A12: G8 | B12: 3224 | C12: 3385 | D12: Exceeding 4900 and not exceeding 5200 | F12: Energy Content | H12: 5500 | I12: kCal/kg
A13: G9 | B13: 2837 | C13: 2912 | D13: 4800 | F13: Energy Content | H13: =H12*1000/860000 -> 6.3953488 | I13: MWh/ton
A14: G10 | B14: 2638 | C14: 2735
A15: G11 | B15: 1969 | C15: 2084 | F15: Coal cost (₹/MWh) | H15: Coal Price/Energy Content(MWh per ton)
A16: G12 | B16: 1744 | C16: 1858 | H16: =$C$11/H13 -> 566.81818 | I16: ₹/MWh
A17: G13 | B17: 1716 | C17: 1849 | F17: Energy Content Lignite | H17: 4800 | I17: kCal/kg
A18: G14 | B18: 1429 | C18: 1511
A19: G15 | B19: 1009 | C19: 1009 | F19: For Grade 8 Coal | H19: between 4900 to 5200 | I19: kCal/kg
A20: G16 | B20: 753 | C20: 753 | F20: Energy Content | H20: 4900 | I20: kCal/kg
A21: G17 | B21: 669 | C21: 669 | F21: Energy Content | H21: =H20*1000/860000 -> 5.6976744 | I21: MWh/ton
A22: ST-I | B22: 22220 | C22: 23153
A23: ST-II | B23: 20175 | C23: 21021 | F23: Coal cost (₹/MWh) | H23: Coal Price/Energy Content(MWh per ton)
A24: W-I | B24: 4854 | C24: 4762 | H24: =$C$12/H21 -> 594.10204 | I24: ₹/MWh
A25: W-II | B25: 4486 | C25: 4202
A26: W-III | B26: 3732 | C26: 3531 | F26: For Grade 8 Coal | H26: between 4900 to 5200 | I26: kCal/kg
A27: W-IV | B27: 3003 | C27: 2999 | F27: Energy Content | H27: 5200 | I27: kCal/kg
F28: Energy Content | H28: =H27*1000/860000 -> 6.0465116 | I28: MWh/ton
F30: Coal cost (₹/MWh) | H30: Coal Price/Energy Content(MWh per ton)
H31: =$C$12/H28 -> 559.82692 | I31: ₹/MWh

Sheet Gas Price
A1: Source | C1: https://ppac.gov.in/natural-gas/gas-price?page=1
A3: Gas Price | B3: 7 | C3: US$/MMBTU | F3: 1MMBtu = 1.055 GJ = 0.293 MWh
B4: =B3*95.08 -> 665.56 | C4: ₹//MMBTU | F4: Exchange Rate 1US $ = 95.08 ₹
F5: 1 MMBtu=252,000 kcal
A6: Heat rate | B6: 3071 | C6: (MCal/MWh) | D6: =B6*1000 -> 3071000 | E6: kCal/MWh
B7: 1423 | C7: (MCal/MWh) | D7: =B7*1000 -> 1423000 | E7: kCal/MWh
B8: 1868 | C8: (MCal/MWh) | D8: =B8*1000 -> 1868000 | E8: kCal/MWh
B10: =D6/252000 -> 12.186508
B11: =B3*B10 -> 85.305556
B12: =B11/0.5 -> 170.61111

Sheet Hydro availability Factor
A1: Source | C1: https://npp.gov.in/dgrReports
A3: https://npp.gov.in/public-reports/cea/daily/dgr/02-07-2026/dgr1-2026-07-02.pdf
A4: https://npp.gov.in/public-reports/cea/daily/dgr/03-07-2026/dgr1-2026-07-03.pdf
A8: https://npp.gov.in/public-reports/cea/daily/dgr/01-07-2026/dgr1-2026-07-01.pdf
A9: https://npp.gov.in/public-reports/cea/daily/dgr/02-07-2026/dgr1-2026-07-02.pdf
A10: https://npp.gov.in/public-reports/cea/daily/dgr/03-07-2026/dgr1-2026-07-03.pdf
A11: https://npp.gov.in/public-reports/cea/daily/dgr/04-07-2026/dgr1-2026-07-04.pdf
A12: https://npp.gov.in/public-reports/cea/daily/dgr/05-07-2026/dgr1-2026-07-05.pdf
A13: https://npp.gov.in/public-reports/cea/daily/dgr/06-07-2026/dgr1-2026-07-06.pdf
A14: https://npp.gov.in/public-reports/cea/daily/dgr/07-07-2026/dgr1-2026-07-07.pdf
A15: https://npp.gov.in/public-reports/cea/daily/dgr/08-07-2026/dgr1-2026-07-08.pdf
A16: https://npp.gov.in/public-reports/cea/daily/dgr/09-07-2026/dgr1-2026-07-09.pdf
A17: https://npp.gov.in/public-reports/cea/daily/dgr/10-07-2026/dgr1-2026-07-10.pdf
... A38: https://npp.gov.in/public-reports/cea/daily/dgr/31-07-2026/dgr1-2026-07-31.pdf

Sheet Solar availability factor
A1: Source | C1: https://iced.niti.gov.in/energy/fuel-sources/solar/irradiance

Sheet Wind availbility factor
A1: Source | C1: https://iced.niti.gov.in/energy/fuel-sources/solar/irradiance
